Workbook

Sheet Sheet1
A1: Sales gas from battery limit | B1: 60FR001.RAW | C1: 60FQI001 | D1: 60FQI001 | E1: T/Day | F1: 1059.5 | G1: =SUM(H1:AL1) -> 715.80968 | H1: =VLOOKUP($B1,'DCS Data'!$E$2:$AJ$100,MATCH('Daily Report'!I$1,'DCS Data'!$E$2:$AJ$2,0),0) -> 715.80968
A2: Sales gas to feed | B2: 60FR005.RAW | C2: 60FQI005 | D2: 60FQI005 | E2: T/Day | F2: 651.6 | G2: =SUM(H2:AL2) -> 506.45477 | H2: =VLOOKUP($B2,'DCS Data'!$E$2:$AJ$100,MATCH('Daily Report'!I$1,'DCS Data'!$E$2:$AJ$2,0),0) -> 506.45477
A3: Feed to Mix point | B3: 60FR009.PV | C3: 60FQI009 | D3: 60FQI009 | E3: T/Day | F3: =F2+F53 -> 655.1 | G3: =SUM(H3:AL3) -> 475.72454 | H3: =VLOOKUP($B3,'DCS Data'!$E$2:$AJ$100,MATCH('Daily Report'!I$1,'DCS Data'!$E$2:$AJ$2,0),0) -> 475.72454
A4: Sales gas to fuel | B4: 60FR049.RAW | C4: 60FQI049 | D4: 60FQI049 | E4: T/Day | F4: 407.9 | G4: =SUM(H4:AL4) -> 296.67809 | H4: =VLOOKUP($B4,'DCS Data'!$E$2:$AJ$100,MATCH('Daily Report'!I$1,'DCS Data'!$E$2:$AJ$2,0),0) -> 296.67809
A5: Sales gas to fuel | B5: 60FR053.PV | C5: 60FQI053 | D5: 60FQI053 | E5: T/Day | F5: 407.9 | G5: =SUM(H5:AL5) -> 326.39421 | H5: =VLOOKUP($B5,'DCS Data'!$E$2:$AJ$100,MATCH('Daily Report'!I$1,'DCS Data'!$E$2:$AJ$2,0),0) -> 326.39421
A6: Sales Gas Average M.Wt | E6: T/Tmole | F6: 17.44 | G6: =AVERAGE(H6:AL6) -> 0.054195789 | H6: =Analysis!J8 -> 0.054195789
A7: HHV | B7: 927QR119.PV | C7: 927QR119 | D7: avg_hhv | E7: btu/scf | F7: 939.07 | G7: =AVERAGE(H7:AL7) -> 958.39106 | H7: =VLOOKUP($B7,'DCS Data'!$E$2:$AJ$100,MATCH('Daily Report'!I$1,'DCS Data'!$E$2:$AJ$2,0),0) -> 958.39106
E8: btu/nm3 | F8: =F7*38.0440529671749 -> 35726.029 | G8: =AVERAGE(H8:AL8) -> 36461.08 | H8: =H7*38.0440529671749 -> 36461.08
A9: Heating value from ARAMCO Metering HHV | E9: btu/nm3 | G9: =AVERAGE(H9:AL9) -> 35799.454 | H9: =H10*38.0440529671749 -> 35799.454
A10: Heating value from ARAMCO Metering HHV | E10: btu/SCF | G10: 941 | H10: =$G$14 -> 941
A11: SELECTED HHV | E11: btu/nm3 | G11: =AVERAGE(H11:AL11) -> 35799.454 | H11: =H9 -> 35799.454
A12: Sales gas Feed Enegy rate | E12: MMBTU/Day | G12: =SUM(H12:AL12) -> 717033.45 | H12: =H11*((H3-H53)*1000/(H6/22.414))/1000000 -> 22007.304
A13: Sales gas Fuel Enegy rate | E13: MMBTU/Day | G13: =SUM(H13:AL13) -> 472230.67 | H13: =H11*(H4*1000/(H6/22.414))/1000000 -> 13826.223
A14: Total Sales gas Enegy rate (AF SalesGas) | E14: MMBTU/Day | G14: =SUM(H14:AL14) -> 1189264.1 | H14: =H13+H12 -> 35833.527
A15: Fresh Gas from sulfinol absorber | B15: 60FR038.RAW | C15: 60FQI038 | D15: 60FQI038 | E15: T/Day | F15: 413.17 | G15: =SUM(H15:AL15) -> 304.7117 | H15: =VLOOKUP($B15,'DCS Data'!$E$2:$AJ$100,MATCH('Daily Report'!I$1,'DCS Data'!$E$2:$AJ$2,0),0) -> 304.7117
A16: Fresh gas to flare (Flare Payment) XOH | B16: 60FR045.RAW | C16: 60FQI045 | D16: 60FQI045 | E16: T/Day | F16: 0 | G16: =SUM(H16:AL16) -> 16.076682 | H16: =VLOOKUP($B16,'DCS Data'!$E$2:$AJ$100,MATCH('Daily Report'!I$1,'DCS Data'!$E$2:$AJ$2,0),0) -> 16.076682
A17: Fresh gas to fuel header | B17: 60FR046.PV | C17: 60FQI046 | D17: 60FQI046 | E17: T/Day | F17: 0 | G17: =SUM(H17:AL17) -> 5.5759268 | H17: =VLOOKUP($B17,'DCS Data'!$E$2:$AJ$100,MATCH('Daily Report'!I$1,'DCS Data'!$E$2:$AJ$2,0),0) -> 5.5759268
A18: Fresh gas to reformer fuel | B18: 60FR050.PV | C18: 60FQI050 | D18: 60FQI050 | E18: T/Day | F18: 0 | G18: =SUM(H18:AL18) -> 0 | H18: =VLOOKUP($B18,'DCS Data'!$E$2:$AJ$100,MATCH('Daily Report'!I$1,'DCS Data'!$E$2:$AJ$2,0),0) -> 0
A19: PSA inlet flow | B19: 61FICA008.PV | C19: 61FQI008 | D19: 61FQI008 | E19: T/Day | F19: 432.1 | G19: =SUM(H19:AL19) -> 0.049699328 | H19: =VLOOKUP($B19,'DCS Data'!$E$2:$AJ$100,MATCH('Daily Report'!I$1,'DCS Data'!$E$2:$AJ$2,0),0) -> 0.049699328
A20: SIPCHEM Import Hydrogen | B20: 170FIA220.PV | C20: 170FQQI220 | D20: 170FQQI220 | E20: T/Day | G20: =SUM(H20:AL20) -> 50.003629 | H20: =VLOOKUP($B20,'DCS Data'!$E$2:$AJ$100,MATCH('Daily Report'!I$1,'DCS Data'!$E$2:$AJ$2,0),0) -> 50.003629
B21: 170FI101.PV | C21: 170FQI101 | D21: 170FQI101 | E21: T/Day | G21: =SUM(H21:AL21) -> 42.514937 | H21: =VLOOKUP($B21,'DCS Data'!$E$2:$AJ$100,MATCH('Daily Report'!I$1,'DCS Data'!$E$2:$AJ$2,0),0) -> 42.514937
A22: Segment#3 H2 | B22: 170FIC121.PV | C22: 170FQI121 | D22: 170FQI121 | E22: T/Day | G22: =SUM(H22:AL22) -> 0 | H22: =VLOOKUP($B22,'DCS Data'!$E$2:$AJ$100,MATCH('Daily Report'!I$1,'DCS Data'!$E$2:$AJ$2,0),0) -> 0
B23: Net SIPCHEM Import | E23: T/Day | G23: =SUM(H23:AL23) -> 7.4886921 | H23: =MAX(H20-H21,H22) -> 7.4886921
A24: HMU H2 outlet | B24: 30FR026.PV | C24: 30FQI026 | D24: 30FQI026 | E24: T/Day | F24: 220 | G24: =SUM(H24:AL24) -> 274.82855 | H24: =VLOOKUP($B24,'DCS Data'!$E$2:$AJ$100,MATCH('Daily Report'!I$1,'DCS Data'!$E$2:$AJ$2,0),0) -> 274.82855
A25: HMU H2 outlet Pressure | B25: 30PR026.PV | C25: 30PR026AI | D25: avg_hmu_h2_outlet_pressure | E25: bar g | G25: =AVERAGE(H25:AL25) -> 14.791534 | H25: =VLOOKUP($B25,'DCS Data'!$E$2:$AJ$100,MATCH('Daily Report'!I$1,'DCS Data'!$E$2:$AJ$2,0),0) -> 14.791534
A26: HMU H2 outlet Temperature | B26: 30TI-316.PV | C26: 30TI-316 | D26: avg_hmu_h2_outlet_temprature | E26: 0C | G26: =AVERAGE(H26:AL26) -> 45.833715 | H26: =VLOOKUP($B26,'DCS Data'!$E$2:$AJ$100,MATCH('Daily Report'!I$1,'DCS Data'!$E$2:$AJ$2,0),0) -> 45.833715
B27: 30-FR-026.COR | E27: T/Day | G27: =SUM(H27:AL27) -> 273.82076 | H27: =(H24*(((57+273)/(H26+273))*(2.6/Analysis!J56)*((H25+1.01325)/(14.6+1.01325)))^0.5)*(Analysis!J56/2.6)-H23 -> 273.82076
A28: PSA outlet | B28: 61FI902.PV | C28: 61FQI902 | D28: avg_psa_outlet | E28: Nm3/hr | F28: 100683.34 | G28: =SUM(H28:AL28) -> 0 | H28: =VLOOKUP($B28,'DCS Data'!$E$2:$AJ$100,MATCH('Daily Report'!I$1,'DCS Data'!$E$2:$AJ$2,0),0) -> 0
E29: T/Day | F29: 220 | G29: =SUM(H29:AL29) -> 0 | H29: =H28*2.01568*24/(22.414*1000) -> 0
B30: 61TIA006.PV | C30: 61TIA006 | D30: 61TIA006 | E30: 0C | F30: 50 | G30: =AVERAGE(H30:AL30) -> 35.699533 | H30: =VLOOKUP($B30,'DCS Data'!$E$2:$AJ$100,MATCH('Daily Report'!I$1,'DCS Data'!$E$2:$AJ$2,0),0) -> 35.699533
B31: 61PICA005.PV | C31: 61PICA005-AI | D31: 61PICA005-AI | E31: barg | F31: 14.1 | G31: =AVERAGE(H31:AL31) -> 14.922634 | H31: =VLOOKUP($B31,'DCS Data'!$E$2:$AJ$100,MATCH('Daily Report'!I$1,'DCS Data'!$E$2:$AJ$2,0),0) -> 14.922634
A32: PSA Bypass flow | B32: 30FR026 - HPSA - Sipchem | E32: T/Day | F32: 50 | G32: =SUM(H32:AL32) -> 266.33207 | H32: =H27-H29-H23 -> 266.33207
B33: 60FR038 - FR45 - FR46 - 61FT008 | E33: T/Day | F33: 50 | G33: =SUM(H33:AL33) -> 283.0094 | H33: =H15-H16-H17-H19 -> 283.0094
A34: Tail gas flow | B34: 61FIA001.PV | C34: 61FQI001 | D34: 61FQI001 | E34: T/Day | F34: 197 | G34: =SUM(H34:AL34) -> 3.0871786 | H34: =VLOOKUP($B34,'DCS Data'!$E$2:$AJ$100,MATCH('Daily Report'!I$1,'DCS Data'!$E$2:$AJ$2,0),0) -> 3.0871786
E35: Nm3/hr | G35: =SUM(H35:AL35) -> 230.6534 | H35: =(H34/24*1000*22.414)/Analysis!J40 -> 230.6534
A36: CCR H2 Flow | E36: Nm3/hr | G36: =SUM(H36:AL36) -> 30276.742 | H36: =(H37/24*1000*22.414)/Analysis!J67 -> 30276.742
A37: CCR Flow (CCRNm) | B37: 170FI001.PV | C37: 170FQI001 | D37: 170FQI001 | E37: T/Day | F37: 150 | G37: =SUM(H37:AL37) -> 110.22495 | H37: =VLOOKUP($B37,'DCS Data'!$E$2:$AJ$100,MATCH('Daily Report'!I$1,'DCS Data'!$E$2:$AJ$2,0),0) -> 110.22495
A38: CCRNHm | E38: T/Day | G38: =SUM(H38:AL38) -> 0 | H38: =(H37/Analysis!J67)*(Analysis!J57/100)*2.015 -> 0
A39: GRHm | E39: T/Day | G39: =SUM(H39:AL39) -> 0 | H39: =(H38*0.856) -> 0
A40: HCU Hydrogen MBU feed | B40: 170FI133.PV | C40: 170FQI133 | D40: 170FQI133 | E40: T/Day | F40: 80 | G40: =SUM(H40:AL40) -> 24.477501 | H40: =VLOOKUP($B40,'DCS Data'!$E$2:$AJ$100,MATCH('Daily Report'!I$1,'DCS Data'!$E$2:$AJ$2,0),0) -> 24.477501
...

Sheet DCS Data
A1: DCS Data | B1: From | C1: 45931 | E1: To | F1: 45962
F2: =F4 -> 45931 | G2: =G4 -> 45932 | H2: =H4 -> 45933 | I2: =I4 -> 45934 | J2: =J4 -> 45935 | K2: =K4 -> 45936 | L2: =L4 -> 45937 | M2: =M4 -> 45938 | ... AJ2: =AJ4 -> 45961
A4: Tags | B4: Descritpion | C4: Units | F4: 45931 | G4: 45932 | H4: 45933 | I4: 45934 | J4: 45935 | K4: 45936 | L4: 45937 | M4: 45938 | N4: 45939 | O4: 45940 | P4: 45941 | Q4: 45942 | R4: 45943 | S4: 45944 | T4: 45945 | U4: 45946 | V4: 45947 | W4: 45948 | X4: 45949 | Y4: 45950 | Z4: 45951 | AA4: 45952 | AB4: 45953 | AC4: 45954 | AD4: 45955 | AE4: 45956 | AF4: 45957 | AG4: 45958 | AH4: 45959 | AI4: 45960 | AJ4: 45961
A5: 60FR001.RAW | B5: Sales gas from battery limit | C5: T/Day | E5: 60FR001.RAW | F5: 715.80968 | G5: 784.31892 | H5: 779.28195 | I5: 776.80468 | J5: 784.98245 | K5: 796.34249 | L5: 792.25577 | M5: 782.73467 | N5: 777.76313 | O5: 784.58269 | P5: 777.22523 | Q5: 778.39093 | R5: 778.24394 | S5: 789.26554 | T5: 778.29253 | U5: 745.81606 | V5: 736.26666 | W5: 746.40695 | X5: 749.23579 | Y5: 765.45979 | Z5: 795.85141 | AA5: 804.30153 | AB5: 802.33001 | AC5: 802.67035 | AD5: 804.8356 | AE5: 802.91544 | AF5: 806.56074 | AG5: 803.92607 | AH5: 800.54275 | AI5: 798.26422 | AJ5: 803.1188
A6: 60FR005.RAW | B6: Sales gas to feed | C6: T/Day | E6: 60FR005.RAW | F6: 506.45477 | G6: 560.94621 | H6: 555.35927 | I6: 553.50791 | J6: 558.76186 | K6: 563.76377 | L6: 559.47536 | M6: 550.52312 | N6: 545.09976 | O6: 548.98877 | P6: 543.37743 | Q6: 544.46673 | R6: 543.40399 | S6: 553.15392 | T6: 542.99368 | U6: 516.40918 | V6: 507.86215 | W6: 517.03235 | X6: 519.08042 | Y6: 532.49508 | Z6: 558.46281 | AA6: 565.74979 | AB6: 562.58084 | AC6: 562.43821 | AD6: 563.90749 | AE6: 562.81016 | AF6: 566.07747 | AG6: 564.24928 | AH6: 561.45119 | AI6: 560.8705 | AJ6: 565.22322
A7: 60FR009.PV | B7: Feed to Mix point | C7: T/Day | E7: 60FR009.PV | F7: 475.72454 | G7: 516.54061 | H7: 512.95876 | I7: 511.42111 | J7: 515.50557 | K7: 521.90849 | L7: 518.61879 | M7: 510.02094 | N7: 503.76427 | O7: 502.97805 | P7: 498.21498 | Q7: 500.01713 | R7: 500.96659 | S7: 507.59104 | T7: 494.90756 | U7: 472.32823 | V7: 463.65063 | W7: 471.92361 | X7: 473.52617 | Y7: 484.07439 | Z7: 506.48072 | AA7: 512.87786 | AB7: 511.49537 | AC7: 510.99099 | AD7: 511.89628 | AE7: 511.40734 | AF7: 512.57256 | AG7: 512.08378 | AH7: 510.16711 | AI7: 510.78699 | AJ7: 513.36321
A8: 60FR049.RAW | B8: Sales gas to fuel | C8: T/Day | E8: 60FR049.RAW | F8: 296.67809 | G8: 321.30663 | H8: 320.61102 | I8: 319.78336 | J8: 323.75165 | K8: 331.00161 | L8: 330.32328 | M8: 328.08213 | N8: 327.44884 | O8: 331.33856 | P8: 328.51127 | Q8: 328.55862 | R8: 329.06011 | S8: 332.32589 | T8: 329.55797 | U8: 318.43173 | V8: 315.96549 | W8: 318.71924 | X8: 319.84994 | Y8: 325.37215 | Z8: 334.97952 | AA8: 337.5278 | AB8: 338.02811 | AC8: 338.61739 | AD8: 339.60751 | AE8: 338.52362 | AF8: 339.64399 | AG8: 338.40416 | AH8: 337.11612 | AI8: 335.2647 | AJ8: 336.56865
A9: 60FR053.PV | B9: Sales gas to fuel | C9: T/Day | E9: 60FR053.PV | F9: 326.39421 | G9: 353.46819 | H9: 353.48294 | I9: 352.80551 | J9: 357.10757 | K9: 364.87162 | L9: 364.13954 | M9: 361.05856 | N9: 359.30059 | O9: 361.13878 | P9: 359.7097 | Q9: 359.9993 | R9: 360.7075 | S9: 363.73028 | T9: 360.11407 | U9: 347.3577 | V9: 343.75912 | W9: 346.71725 | X9: 348.05626 | Y9: 353.79562 | Z9: 363.99381 | AA9: 366.48532 | AB9: 367.27025 | AC9: 366.9853 | AD9: 367.7212 | AE9: 367.52925 | AF9: 368.73711 | AG9: 368.58301 | AH9: 367.68908 | AI9: 365.96502 | AJ9: 367.36664
A10: 927QR119.PV | B10: HHV | C10: btu/scf | E10: 927QR119.PV | F10: 958.39106 | G10: 958.70493 | H10: 960.17631 | I10: 959.67176 | J10: 958.7671 | K10: 958.31932 | L10: 957.79165 | M10: 957.99171 | N10: 954.28132 | O10: 947.26019 | P10: 948.81396 | Q10: 949.15434 | R10: 947.40148 | S10: 946.8692 | T10: 947.78363 | U10: 944.75878 | V10: 943.78013 | W10: 942.8891 | X10: 944.09768 | Y10: 945.16817 | Z10: 945.14419 | AA10: 945.20913 | AB10: 944.71295 | AC10: 943.43437 | AD10: 941.02151 | AE10: 943.80364 | AF10: 944.19124 | AG10: 943.73163 | AH10: 944.58824 | AI10: 946.42698 | AJ10: 946.04552
A11: 60FR038.RAW | B11: Fresh Gas from sulfinol absorber | C11: T/Day | E11: 60FR038.RAW | F11: 304.7117 | G11: 334.80949 | H11: 333.98059 | I11: 332.17693 | J11: 335.66792 | K11: 337.06501 | L11: 335.78726 | M11: 330.61216 | N11: 326.62464 | O11: 324.67558 | P11: 322.11682 | Q11: 323.61347 | R11: 325.3412 | S11: 330.71711 | T11: 322.75248 | U11: 306.27948 | V11: 302.32247 | W11: 308.79103 | X11: 309.74099 | Y11: 316.34794 | Z11: 330.14889 | AA11: 333.94923 | AB11: 332.47882 | AC11: 330.76732 | AD11: 329.67151 | AE11: 331.85693 | AF11: 332.04673 | AG11: 334.15962 | AH11: 331.4246 | AI11: 333.44615 | AJ11: 336.5901
A12: 60FR045.RAW | B12: Fresh gas to flare (Flare Payment) XOH | C12: T/Day | E12: 60FR045.RAW | F12: 16.076682 | G12: 15.097068 | H12: 14.873856 | I12: 14.599687 | J12: 14.090603 | K12: 13.464697 | L12: 12.752191 | M12: 12.143387 | N12: 11.541502 | O12: 10.117407 | P12: 9.4803942 | Q12: 8.9027436 | R12: 8.3962262 | S12: 7.1514769 | T12: 14.856918 | U12: 60.756173 | V12: 95.080269 | W12: 127.31549 | X12: 130.13167 | Y12: 54.203551 | Z12: 5.7179578 | AA12: 0.45307881 | AB12: 0.180822 | AC12: 0.15496849 | AD12: 0.15404499 | AE12: 0.17434642 | AF12: 0.2493058 | AG12: 2.3570345 | AH12: 0.48982095 | AI12: 0.30648619 | AJ12: 0.2430548
A13: 60FR046.PV | B13: Fresh gas to fuel header | C13: T/Day | E13: 60FR046.PV | F13: 5.5759268 | G13: 4.7301031 | H13: 2.4825299 | I13: 3.0244137 | J13: 5.8323364 | K13: 4.2850126 | L13: 4.241413 | M13: 2.1824402 | N13: 2.9270617 | O13: 4.1774717 | P13: 3.2595885 | Q13: 3.5562102 | R13: 1.4409001 | S13: 4.4529352 | T13: 3.8035433 | U13: 8.4709132 | V13: 10.00008 | W13: 9.9998461 | X13: 10.000028 | Y13: 9.999848 | Z13: 8.21407 | AA13: 4.7524919 | AB13: 2.3901843 | AC13: 4.6096234 | AD13: 4.2034424 | AE13: 4.8607463 | AF13: 3.6985965 | AG13: 4.3497944 | AH13: 2.2328551 | AI13: 2.772445 | AJ13: 2.8229364
A14: 30FR026.PV | B14: HMU H2 outlet | C14: T/Day | E14: 30FR026.PV | F14: 274.82855 | G14: 316.5105 | H14: 324.81535 | I14: 323.96956 | J14: 322.12721 | K14: 325.39024 | L14: 323.85949 | M14: 320.90933 | N14: 316.56838 | O14: 315.0714 | P14: 312.77127 | Q14: 312.58605 | R14: 314.31778 | S14: 316.32039 | T14: 302.15751 | U14: 287.58504 | V14: 301.40063 | W14: 295.97471 | X14: 295.67676 | Y14: 308.61499 | Z14: 324.41094 | AA14: 331.73015 | AB14: 332.64328 | AC14: 329.75786 | AD14: 330.30353 | AE14: 325.83511 | AF14: 320.31557 | AG14: 319.57131 | AH14: 320.50145 | AI14: 319.84349 | AJ14: 322.06536
A15: 30PR026.PV | B15: HMU H2 outlet Pressure | C15: bar g | E15: 30PR026.PV | F15: 14.791534 | G15: 14.781141 | H15: 14.698188 | I15: 14.754153 | J15: 14.786065 | K15: 14.805844 | L15: 14.789062 | M15: 14.748245 | N15: 14.792283 | O15: 14.813199 | P15: 14.813352 | Q15: 14.813956 | R15: 14.769625 | S15: 14.723863 | T15: 14.648699 | U15: 14.805692 | V15: 14.776518 | W15: 14.768816 | X15: 14.763986 | Y15: 14.722531 | Z15: 14.629462 | AA15: 14.604606 | AB15: 14.570097 | AC15: 14.594384 | AD15: 14.599882 | AE15: 14.554708 | AF15: 14.617502 | AG15: 14.61938 | AH15: 14.565363 | AI15: 14.567158 | AJ15: 14.559003
A16: 30TI-316.PV | B16: HMU H2 outlet Temperature | C16: 0C | E16: 30TI-316.PV | F16: 45.833715 | G16: 45.017124 | H16: 44.405759 | I16: 43.565906 | J16: 43.995716 | K16: 44.407769 | L16: 44.868529 | M16: 44.79797 | N16: 44.403776 | O16: 43.456368 | P16: 41.730205 | Q16: 41.375325 | R16: 42.122633 | S16: 42.509301 | T16: 33.23064 | U16: 31.809339 | V16: 31.833472 | W16: 31.963925 | X16: 32.004293 | Y16: 33.326123 | Z16: 33.677247 | AA16: 33.553582 | AB16: 33.61099 | AC16: 34.11326 | AD16: 34.317561 | AE16: 34.499035 | AF16: 33.71468 | AG16: 33.497321 | AH16: 33.05379 | AI16: 33.165185 | AJ16: 32.992042
... A19: 170FIA220.PV | B19: SIPCHEM Import Hydrogen | C19: T/Day | E19: 170FIA220.PV | F19: 50.003629 | G19: 54.568473 | H19: 57.751508 | I19: 58.535966 | J19: 55.454159 | K19: 51.834799 | L19: 51.096089 | M19: 51.207506 | N19: 50.714458 | O19: 50.611381 | P19: 50.716608 | Q19: 50.755757 | R19: 51.75571 | S19: 50.198807 | T19: 72.608428 | U19: 101.36589 | V19: 128.1645 | W19: 144.64532 | X19: 142.54977 | Y19: 94.192294 | Z19: 56.254848 | AA19: 49.780023 | AB19: 49.091665 | AC19: 50.696657 | AD19: 52.619838 | AE19: 55.571303 | AF19: 52.678048 | AG19: 51.329472 | AH19: 49.792494 | AI19: 51.515082 | AJ19: 50.309055
A20: 170FI101.PV | B20: 0 | C20: T/Day | E20: 170FI101.PV | F20: 42.514937 | G20: 41.895091 | H20: 39.920453 | I20: 39.451488 | J20: 38.589994 | K20: 37.02885 | L20: 37.033204 | M20: 36.924792 | N20: 37.573208 | O20: 37.692364 | P20: 37.571163 | Q20: 37.104439 | R20: 39.578595 | S20: 37.158481 | T20: 36.654369 | U20: 30.999881 | V20: 10.444701 | W20: 7.7706708 | X20: 2.7240041 | Y20: 18.1375 | Z20: 24.120858 | AA20: 24.665634 | AB20: 26.442972 | AC20: 27.777391 | AD20: 29.457533 | AE20: 36.201672 | AF20: 39.535632 | AG20: 38.241806 | AH20: 36.845225 | AI20: 38.170471 | AJ20: 37.245255
A21: 170FIC121.PV | B21: Segment#3 H2 | C21: T/Day | E21: 170FIC121.PV | F21: 0 | G21: 0 | H21: 0 | I21: 0 | J21: 0 | K21: 0 | L21: 0 | M21: 0 | N21: 0.92220037 | O21: 0 | P21: 0 | Q21: 0 | R21: 0 | S21: 0.020709153 | T21: 25.502183 | U21: 67.978179 | V21: 108.60924 | W21: 124.34291 | X21: 125.19551 | Y21: 73.14968 | Z21: 36.896744 | AA21: 32.996241 | AB21: 32.996896 | AC21: 33.000006 | AD21: 32.998697 | AE21: 29.371404 | AF21: 23.99898 | AG21: 23.996102 | AH21: 23.999714 | AI21: 23.998939 | AJ21: 23.99913
A22: 30FR026.PV | B22: HMU H2 outlet | C22: T/Day | E22: 30FR026.PV | F22: 274.82855 | G22: 316.5105 | H22: 324.81535 | I22: 323.96956 | J22: 322.12721 | K22: 325.39024 | L22: 323.85949 | M22: 320.90933 | N22: 316.56838 | O22: 315.0714 | P22: 312.77127 | Q22: 312.58605 | R22: 314.31778 | S22: 316.32039 | T22: 302.15751 | U22: 287.58504 | V22: 301.40063 | W22: 295.97471 | X22: 295.67676 | Y22: 308.61499 | Z22: 324.41094 | AA22: 331.73015 | AB22: 332.64328 | AC22: 329.75786 | AD22: 330.30353 | AE22: 325.83511 | AF22: 320.31557 | AG22: 319.57131 | AH22: 320.50145 | AI22: 319.84349 | AJ22: 322.06536
A23: 30PR026.PV | B23: HMU H2 outlet Pressure | C23: bar g | E23: 30PR026.PV | F23: 14.791534 | G23: 14.781141 | H23: 14.698188 | I23: 14.754153 | J23: 14.786065 | K23: 14.805844 | L23: 14.789062 | M23: 14.748245 | N23: 14.792283 | O23: 14.813199 | P23: 14.813352 | Q23: 14.813956 | R23: 14.769625 | S23: 14.723863 | T23: 14.648699 | U23: 14.805692 | V23: 14.776518 | W23: 14.768816 | X23: 14.763986 | Y23: 14.722531 | Z23: 14.629462 | AA23: 14.604606 | AB23: 14.570097 | AC23: 14.594384 | AD23: 14.599882 | AE23: 14.554708 | AF23: 14.617502 | AG23: 14.61938 | AH23: 14.565363 | AI23: 14.567158 | AJ23: 14.559003
A24: 30TI-316.PV | B24: HMU H2 outlet Temperature | C24: 0C | E24: 30TI-316.PV | F24: 45.833715 | G24: 45.017124 | H24: 44.405759 | I24: 43.565906 | J24: 43.995716 | K24: 44.407769 | L24: 44.868529 | M24: 44.79797 | N24: 44.403776 | O24: 43.456368 | P24: 41.730205 | Q24: 41.375325 | R24: 42.122633 | S24: 42.509301 | T24: 33.23064 | U24: 31.809339 | V24: 31.833472 | W24: 31.963925 | X24: 32.004293 | Y24: 33.326123 | Z24: 33.677247 | AA24: 33.553582 | AB24: 33.61099 | AC24: 34.11326 | AD24: 34.317561 | AE24: 34.499035 | AF24: 33.71468 | AG24: 33.497321 | AH24: 33.05379 | AI24: 33.165185 | AJ24: 32.992042
A25: 61FI902.PV | B25: PSA outlet | C25: Nm3/hr | E25: 61FI902.PV | F25: 0 | G25: 0 | H25: 0 | I25: 0 | J25: 0 | K25: 0 | L25: 0 | M25: 0 | N25: 0 | O25: 0 | P25: 0 | Q25: 0 | R25: 0 | S25: 0 | T25: 0 | U25: 0 | V25: 0 | W25: 0 | X25: 0 | Y25: 0 | Z25: 0 | AA25: 0 | AB25: 0 | AC25: 0 | AD25: 0 | AE25: 0 | AF25: 0 | AG25: 0 | AH25: 0 | AI25: 0 | AJ25: 0
A26: 61TIA006.PV | B26: 0 | C26: 0C | E26: 61TIA006.PV | F26: 35.699533 | G26: 34.218017 | H26: 33.083199 | I26: 32.021844 | J26: 32.210174 | K26: 32.276263 | L26: 32.325023 | M26: 32.860623 | N26: 32.386852 | O26: 32.514522 | P26: 32.084796 | Q26: 31.769091 | R26: 31.277299 | S26: 31.10505 | T26: 30.415614 | U26: 29.472775 | V26: 28.854502 | W26: 30.346151 | X26: 31.216799 | Y26: 32.893786 | Z26: 33.499515 | AA26: 33.575397 | AB26: 33.683301 | AC26: 33.896609 | AD26: 34.081653 | AE26: 34.137107 | AF26: 33.530558 | AG26: 33.408085 | AH26: 33.053017 | AI26: 33.442722 | AJ26: 33.505228
A27: 61PICA005.PV | B27: 0 | C27: barg | E27: 61PICA005.PV | F27: 14.922634 | G27: 14.961403 | H27: 14.889737 | I27: 14.944578 | J27: 14.97448 | K27: 14.998138 | L27: 14.979302 | M27: 14.93479 | N27: 14.97309 | O27: 14.991307 | P27: 14.987799 | Q27: 14.988482 | R27: 14.946539 | S27: 14.903167 | T27: 14.838598 | U27: 14.960736 | V27: 14.938817 | W27: 14.919281 | X27: 14.913744 | Y27: 14.907363 | Z27: 14.853332 | AA27: 14.841869 | AB27: 14.809299 | AC27: 14.828713 | AD27: 14.834826 | AE27: 14.783987 | AF27: 14.839399 | AG27: 14.83987 | AH27: 14.788296 | AI27: 14.788884 | AJ27: 14.783749
A28: 61FIA001.PV | B28: Tail gas flow | C28: T/Day | E28: 61FIA001.PV | F28: 3.0871786 | G28: 2.7146487 | H28: 3.6532282 | I28: 2.3064332 | J28: 4.0765575 | K28: 4.4982554 | L28: 3.0833336 | M28: 4.7681145 | N28: 4.938609 | O28: 3.2229353 | P28: 3.9762938 | Q28: 3.6808537 | R28: 5.2230497 | S28: 5.3124402 | T28: 3.8013143 | U28: 5.1770699 | V28: 4.8760733 | W28: 3.4629964 | X28: 3.3564982 | Y28: 3.6666256 | Z28: 5.6031459 | AA28: 5.4325662 | AB28: 3.546705 | AC28: 2.4319089 | AD28: 4.5649791 | AE28: 5.3802403 | AF28: 3.8096496 | AG28: 5.5141856 | AH28: 6.0042394 | AI28: 5.3021927 | AJ28: 5.9448977
A29: 170FI001.PV | B29: CCR Flow (CCRNm) | C29: T/Day | E29: 170FI001.PV | F29: 110.22495 | G29: 116.2964 | H29: 122.74262 | I29: 116.57718 | J29: 122.01672 | K29: 109.77968 | L29: 103.48487 | M29: 109.85216 | N29: 111.59765 | O29: 104.71736 | P29: 115.70893 | Q29: 124.32578 | R29: 107.23534 | S29: 101.4968 | T29: 113.27158 | U29: 126.3277 | V29: 101.15028 | W29: 87.632604 | X29: 108.27424 | Y29: 113.14295 | Z29: 120.09942 | AA29: 118.15901 | AB29: 120.30545 | AC29: 120.93408 | AD29: 119.60411 | AE29: 114.44017 | AF29: 120.28162 | AG29: 127.403 | AH29: 128.1381 | AI29: 125.25052 | AJ29: 132.71256
A30: 170FI133.PV | B30: HCU Hydrogen MBU feed | C30: T/Day | E30: 170FI133.PV | F30: 24.477501 | G30: 33.983244 | H30: 36.107213 | I30: 37.164721 | J30: 37.631567 | K30: 40.745531 | L30: 40.31662 | M30: 37.142195 | N30: 32.496637 | O30: 32.236323 | P30: 29.357789 | Q30: 28.094096 | R30: 26.632763 | S30: 29.980252 | T30: 24.741271 | U30: 32.340709 | V30: 65.376473 | W30: 66.503893 | X30: 71.130357 | Y30: 56.752043 | Z30: 49.591735 | AA30: 52.567635 | AB30: 52.677269 | AC30: 51.18214 | AD30: 52.087284 | AE30: 44.730946 | AF30: 38.731954 | AG30: 38.948852 | AH30: 39.592446 | AI30: 37.661915 | AJ30: 39.659145
A31: 170FICA174.PV | B31: Total feed to MBU | C31: Nm3/hr | E31: 170FICA174.PV | F31: 24821.648 | G31: 28786.42 | H31: 30135.142 | I31: 29695.882 | J31: 30106.105 | K31: 29652.104 | L31: 28896.149 | M31: 28592.455 | N31: 27476.735 | O31: 26490.609 | P31: 27179.612 | Q31: 27922.321 | R31: 25221.501 | S31: 25518.396 | T31: 25565.752 | U31: 29566.34 | V31: 37084.687 | W31: 35882.165 | X31: 39787.871 | Y31: 35808.778 | Z31: 34506.199 | AA31: 35198.429 | AB31: 35595.842 | AC31: 35091.332 | AD31: 35063.166 | AE31: 32154.116 | AF31: 31066.677 | AG31: 32209.792 | AH31: 32590.046 | AI31: 31520.243 | AJ31: 33290.117
A32: 170X124.PV | B32: Residue gas flow from MBU | C32: Nm3/hr | E32: 170X124.PV | F32: 4285.6784 | G32: 5028.692 | H32: 5042.1981 | I32: 4953.876 | J32: 5149.5744 | K32: 4129.7024 | L32: 3857.6451 | M32: 4032.5316 | N32: 3879.2521 | O32: 3608.1029 | P32: 4019.4915 | Q32: 4358.4767 | R32: 3043.4934 | S32: 2988.4809 | T32: 3343.9569 | U32: 4493.3132 | V32: 5596.0269 | W32: 5420.7371 | X32: 5536.2503 | Y32: 5208.7093 | Z32: 5046.16 | AA32: 5122.1943 | AB32: 5195.8352 | AC32: 5158.5779 | AD32: 5157.0843 | AE32: 5003.7884 | AF32: 4965.1698 | AG32: 5164.8143 | AH32: 5194.834 | AI32: 5135.671 | AJ32: 5234.0544
A33: 170X125.PV | B33: 0 | C33: Nm3/hr | E33: 170X125.PV | F33: 4276.2713 | G33: 5019.5818 | H33: 5033.4901 | I33: 4944.7211 | J33: 5140.0736 | K33: 4119.734 | L33: 3847.2568 | M33: 4022.6476 | N33: 3868.9918 | O33: 3597.6639 | P33: 4009.6531 | Q33: 4349.0287 | R33: 3032.2902 | S33: 2977.384 | T33: 3332.8176 | U33: 4483.8372 | V33: 5586.7676 | W33: 5411.5403 | X33: 5526.0117 | Y33: 5198.6593 | Z33: 5036.0342 | AA33: 5112.5101 | AB33: 5185.6322 | AC33: 5148.3286 | AD33: 5147.0867 | AE33: 4994.2496 | AF33: 4955.3888 | AG33: 5155.6111 | AH33: 5184.9065 | AI33: 5125.8336 | AJ33: 5224.4453
A34: 170FIA175.PV | B34: Average Residue gas flow from MBU | C34: Nm3/hr | E34: 170FIA175.PV | F34: 4280.8489 | G34: 5024.1802 | H34: 5037.7402 | I34: 4949.2902 | J34: 5144.8054 | K34: 4124.725 | L34: 3852.4412 | M34: 4027.5092 | N34: 3874.137 | O34: 3602.9722 | P34: 4014.5364 | Q34: 4353.7892 | R34: 3037.8903 | S34: 2982.9555 | T34: 3338.2596 | U34: 4488.3215 | V34: 5591.3378 | W34: 5415.955 | X34: 5531.1233 | Y34: 5203.7501 | Z34: 5041.2108 | AA34: 5117.4294 | AB34: 5190.688 | AC34: 5153.5185 | AD34: 5151.9954 | AE34: 4999.063 | AF34: 4960.3908 | AG34: 5160.0698 | AH34: 5189.7803 | AI34: 5130.7588 | AJ34: 5229.0935
A35: 170PEA329.PV | B35: Residue gas Pressure | C35: barg | E35: 170PEA329.PV | F35: 33.323315 | G35: 33.005304 | H35: 32.223748 | I35: 31.803625 | J35: 32.590492 | K35: 32.997533 | L35: 32.844153 | M35: 32.800428 | N35: 32.799305 | O35: 32.799931 | P35: 32.800974 | Q35: 32.799969 | R35: 32.797633 | S35: 32.781341 | T35: 32.984185 | U35: 33.688829 | V35: 33.135062 | W35: 31.815974 | X35: 34.578806 | Y35: 34.634784 | Z35: 34.57246 | AA35: 34.601881 | AB35: 34.582916 | AC35: 34.583143 | AD35: 34.540716 | AE35: 33.154172 | AF35: 33.183831 | AG35: 33.801672 | AH35: 33.980108 | AI35: 33.362763 | AJ35: 34.457049
A36: 170PEA469.PV | B36: MBU Feed Pressure | C36: barg | E36: 170PEA469.PV | F36: 33.749769 | G36: 33.532567 | H36: 32.774762 | I36: 32.338811 | J36: 33.154825 | K36: 33.465845 | L36: 33.278707 | M36: 33.250927 | N36: 33.223529 | O36: 33.188207 | P36: 33.232006 | Q36: 33.27303 | R36: 33.128569 | S36: 33.108984 | T36: 33.342194 | U36: 34.192924 | V36: 33.803752 | W36: 32.422048 | X36: 35.263334 | Y36: 35.252032 | Z36: 35.176696 | AA36: 35.219349 | AB36: 35.209896 | AC36: 35.201867 | AD36: 35.158866 | AE36: 33.718596 | AF36: 33.735409 | AG36: 34.392022 | AH36: 34.576943 | AI36: 33.937629 | AJ36: 35.067803
A37: 60FR006.PV | B37: Recycle Hydrogen | C37: T/Day | E37: 60FR006.PV | F37: 3.4997912 | G37: 3.4996422 | H37: 3.4998225 | I37: 3.5001772 | J37: 3.500037 | K37: 3.4999756 | L37: 3.4998563 | M37: 3.4997384 | N37: 3.4999437 | O37: 3.5002459 | P37: 3.5000612 | Q37: 3.4999062 | R37: 3.5000269 | S37: 3.4998735 | T37: 3.4998924 | U37: 3.4998975 | V37: 3.5000462 | W37: 3.4999051 | X37: 3.4997082 | Y37: 3.4999716 | Z37: 3.5002829 | AA37: 3.4999263 | AB37: 3.500138 | AC37: 3.4999511 | AD37: 3.4999887 | AE37: 3.5000126 | AF37: 3.4999312 | AG37: 3.5000869 | AH37: 3.5000864 | AI37: 3.4998705 | AJ37: 3.4998577
A38: 170STR2CMAS.PV | B38: Import Hydrogen from ALAR | C38: T/Day | E38: 170STR2CMAS.PV | F38: 8.0266814 | G38: 11.578448 | H38: 11.953033 | I38: 12.075272 | J38: 12.060503 | K38: 12.136466 | L38: 12.583467 | M38: 12.286708 | N38: 14.308877 | O38: 15.039738 | P38: 14.747527 | Q38: 14.262079 | R38: 14.212352 | S38: 14.094345 | T38: 14.101891 | U38: 13.918447 | V38: 13.882125 | W38: 13.840987 | X38: 13.644897 | Y38: 12.958607 | Z38: 14.461661 | AA38: 16.995294 | AB38: 19.771211 | AC38: 19.57701 | AD38: 19.43251 | AE38: 19.62022 | AF38: 19.790423 | AG38: 19.848534 | AH38: 19.872613 | AI38: 19.734871 | AJ38: 19.967848
A39: 60TR027.PV | B39: SMR Inlet Temperature | C39: 0C | E39: 60TR027.PV | F39: 449.22198 | G39: 446.57338 | H39: 446.91044 | I39: 447.77019 | J39: 453.45572 | K39: 459.30698 | L39: 459.21824 | M39: 459.5228 | N39: 460.96198 | O39: 461.54839 | P39: 461.70668 | Q39: 461.77753 | R39: 461.92291 | S39: 460.98038 | T39: 461.35592 | U39: 465.56727 | V39: 464.54759 | W39: 463.52702 | X39: 461.72902 | Y39: 458.00612 | Z39: 457.34157 | AA39: 458.0555 | AB39: 457.62957 | AC39: 457.50145 | AD39: 456.74539 | AE39: 456.20761 | AF39: 456.48033 | AG39: 457.49916 | AH39: 457.81814 | AI39: 457.77064 | AJ39: 457.66104
A40: 60TR028.PV | B40: SMR Outlet Temperature | C40: 0C | E40: 60TR028.PV | F40: 798.54952 | G40: 800.26996 | H40: 803.07766 | I40: 802.97043 | J40: 802.57538 | K40: 802.9955 | L40: 803.0202 | M40: 803.11795 | N40: 802.9595 | O40: 803.03401 | P40: 802.95933 | Q40: 803.00768 | R40: 803.00266 | S40: 802.90557 | T40: 803.19932 | U40: 803.24093 | V40: 803.02695 | W40: 802.92293 | X40: 803.01269 | Y40: 802.63714 | Z40: 802.92086 | AA40: 802.95029 | AB40: 803.00996 | AC40: 802.96625 | AD40: 802.97974 | AE40: 802.97437 | AF40: 803.00939 | AG40: 803.00102 | AH40: 803.056 | AI40: 803.00998 | AJ40: 803.00174
A41: 60FR054.PV | B41: Combustion Air Flow | C41: T/Day | E41: 60FR054.PV | F41: 4731.0128 | G41: 5068.4044 | H41: 5121.3145 | I41: 5130.2947 | J41: 5410.7452 | K41: 5931.087 | L41: 5941.6708 | M41: 5934.052 | N41: 5945.3784 | O41: 5888.8034 | P41: 5852.472 | Q41: 5935.8742 | R41: 5973.9277 | S41: 5911.7084 | T41: 5886.7534 | U41: 5904.6682 | V41: 5938.356 | W41: 5950.276 | X41: 5954.1084 | Y41: 5906.186 | Z41: 5891.7913 | AA41: 5944.1207 | AB41: 5948.0721 | AC41: 5929.5219 | AD41: 5944.0895 | AE41: 5921.6944 | AF41: 5919.4018 | AG41: 5905.037 | AH41: 5925.8355 | AI41: 5969.6921 | AJ41: 5977.6852
A42: 60TR035.PV | B42: HTS Inlet Temperature | C42: 0C | E42: 60TR035.PV | F42: 325.71572 | G42: 328.80409 | H42: 329.16441 | I42: 329.31585 | J42: 329.35532 | K42: 330.16962 | L42: 330.43694 | M42: 330.43532 | N42: 329.74578 | O42: 329.52192 | P42: 329.27115 | Q42: 329.50793 | R42: 330.06323 | S42: 330.36979 | T42: 329.41531 | U42: 325.81909 | V42: 324.61581 | W42: 324.86182 | X42: 325.80557 | Y42: 327.31231 | Z42: 329.57589 | AA42: 330.03021 | AB42: 331.05128 | AC42: 331.35504 | AD42: 331.66137 | AE42: 331.93905 | AF42: 331.61963 | AG42: 331.63543 | AH42: 331.70022 | AI42: 331.52794 | AJ42: 331.40384
A43: 60TR036.PV | B43: 0 | C43: 0C | E43: 60TR036.PV | F43: 368.50433 | G43: 372.53179 | H43: 372.99572 | I43: 373.07681 | J43: 373.50677 | K43: 374.45004 | L43: 374.32473 | M43: 373.69074 | N43: 372.94176 | O43: 372.55796 | P43: 372.33245 | Q43: 372.62669 | R43: 372.8517 | S43: 373.39655 | T43: 372.5295 | U43: 370.10586 | V43: 369.34926 | W43: 370.18547 | X43: 370.6523 | Y43: 371.71998 | Z43: 373.9971 | AA43: 374.68036 | AB43: 374.56732 | AC43: 374.49303 | AD43: 374.5483 | AE43: 374.75652 | AF43: 374.93321 | AG43: 374.98546 | AH43: 375.00362 | AI43: 375.23394 | AJ43: 375.55506
...

Sheet Daily Report
A1: BHIG/SASREF DAILY REPORT Date DD/MM/YYYY | H1: Monthly Records | I1: ='DCS Data'!F$2 -> 45931 | K1: ='DCS Data'!G$2 -> 45932 | L1: ='DCS Data'!H$2 -> 45933 | M1: ='DCS Data'!I$2 -> 45934 | N1: ='DCS Data'!J$2 -> 45935 | O1: ='DCS Data'!K$2 -> 45936 | P1: ='DCS Data'!L$2 -> 45937 | Q1: ='DCS Data'!M$2 -> 45938 | R1: ='DCS Data'!N$2 -> 45939 | ... AN1: ='DCS Data'!AJ$2 -> 45961
A2: Parameter | B2: Previous Tag | C2: Current Tag | E2: UOM | F2: HMB
A3: Plant load | E3: % | G3: monthly_calc_plant_load | H3: =AVERAGE(I3:AN3) -> 84.244127 | I3: =((I6)/$F$6)*100 -> 77.724796 | K3: =((K6)/$F$6)*100 -> 86.087509 | L3: =((L6)/$F$6)*100 -> 85.230091 | M3: =((M6)/$F$6)*100 -> 84.945966 | N3: =((N6)/$F$6)*100 -> 85.752281 | O3: =((O6)/$F$6)*100 -> 86.519915 | P3: =((P6)/$F$6)*100 -> 85.86178 | Q3: =((Q6)/$F$6)*100 -> 84.487894 | R3: =((R6)/$F$6)*100 -> 83.65558 | ... AN3: =((AN6)/$F$6)*100 -> 86.743895
A4: Operation Hours | E4: Hrs | F4: 24 | G4: monthly_operation_hours | H4: =SUM(I4:AN4) -> 744 | I4: 24 | K4: 24 | L4: 24 | M4: 24 | N4: 24 | O4: 24 | P4: 24 | Q4: 24 | R4: 24 | S4: 24 | T4: 24 | U4: 24 | V4: 24 | W4: 24 | X4: 24 | Y4: 24 | Z4: 24 | AA4: 24 | AB4: 24 | AC4: 24 | AD4: 24 | AE4: 24 | AF4: 24 | AG4: 24 | AH4: 24 | AI4: 24 | AJ4: 24 | AK4: 24 | AL4: 24 | AM4: 24 | AN4: 24
A5: Sales gas from battery limit | B5: 60FR001.RAW | C5: 60FQI001 | D5: 60FQI001 | E5: T/Day | F5: 1059.5 | G5: monthly_60FQI001 | H5: =SUM(I5:AN5) -> 24244.797 | I5: =VLOOKUP($B5,'DCS Data'!$E$2:$AJ$100,MATCH('Daily Report'!I$1,'DCS Data'!$E$2:$AJ$2,0),0) -> 715.80968 | K5: =VLOOKUP($B5,'DCS Data'!$E$2:$AJ$100,MATCH('Daily Report'!K$1,'DCS Data'!$E$2:$AJ$2,0),0) -> 784.31892 | L5: =VLOOKUP($B5,'DCS Data'!$E$2:$AJ$100,MATCH('Daily Report'!L$1,'DCS Data'!$E$2:$AJ$2,0),0) -> 779.28195 | M5: =VLOOKUP($B5,'DCS Data'!$E$2:$AJ$100,MATCH('Daily Report'!M$1,'DCS Data'!$E$2:$AJ$2,0),0) -> 776.80468 | N5: =VLOOKUP($B5,'DCS Data'!$E$2:$AJ$100,MATCH('Daily Report'!N$1,'DCS Data'!$E$2:$AJ$2,0),0) -> 784.98245 | O5: =VLOOKUP($B5,'DCS Data'!$E$2:$AJ$100,MATCH('Daily Report'!O$1,'DCS Data'!$E$2:$AJ$2,0),0) -> 796.34249 | P5: =VLOOKUP($B5,'DCS Data'!$E$2:$AJ$100,MATCH('Daily Report'!P$1,'DCS Data'!$E$2:$AJ$2,0),0) -> 792.25577 | Q5: =VLOOKUP($B5,'DCS Data'!$E$2:$AJ$100,MATCH('Daily Report'!Q$1,'DCS Data'!$E$2:$AJ$2,0),0) -> 782.73467 | R5: =VLOOKUP($B5,'DCS Data'!$E$2:$AJ$100,MATCH('Daily Report'!R$1,'DCS Data'!$E$2:$AJ$2,0),0) -> 777.76313 | ... AN5: =VLOOKUP($B5,'DCS Data'!$E$2:$AJ$100,MATCH('Daily Report'!AN$1,'DCS Data'!$E$2:$AJ$2,0),0) -> 803.1188
A6: Sales gas to feed | B6: 60FR005.RAW | C6: 60FQI005 | D6: 60FQI005 | E6: T/Day | F6: 651.6 | G6: monthly_60FQI005 | H6: =SUM(I6:AN6) -> 17016.977 | I6: =VLOOKUP($B6,'DCS Data'!$E$2:$AJ$100,MATCH('Daily Report'!I$1,'DCS Data'!$E$2:$AJ$2,0),0) -> 506.45477 | K6: =VLOOKUP($B6,'DCS Data'!$E$2:$AJ$100,MATCH('Daily Report'!K$1,'DCS Data'!$E$2:$AJ$2,0),0) -> 560.94621 | L6: =VLOOKUP($B6,'DCS Data'!$E$2:$AJ$100,MATCH('Daily Report'!L$1,'DCS Data'!$E$2:$AJ$2,0),0) -> 555.35927 | M6: =VLOOKUP($B6,'DCS Data'!$E$2:$AJ$100,MATCH('Daily Report'!M$1,'DCS Data'!$E$2:$AJ$2,0),0) -> 553.50791 | N6: =VLOOKUP($B6,'DCS Data'!$E$2:$AJ$100,MATCH('Daily Report'!N$1,'DCS Data'!$E$2:$AJ$2,0),0) -> 558.76186 | O6: =VLOOKUP($B6,'DCS Data'!$E$2:$AJ$100,MATCH('Daily Report'!O$1,'DCS Data'!$E$2:$AJ$2,0),0) -> 563.76377 | P6: =VLOOKUP($B6,'DCS Data'!$E$2:$AJ$100,MATCH('Daily Report'!P$1,'DCS Data'!$E$2:$AJ$2,0),0) -> 559.47536 | Q6: =VLOOKUP($B6,'DCS Data'!$E$2:$AJ$100,MATCH('Daily Report'!Q$1,'DCS Data'!$E$2:$AJ$2,0),0) -> 550.52312 | R6: =VLOOKUP($B6,'DCS Data'!$E$2:$AJ$100,MATCH('Daily Report'!R$1,'DCS Data'!$E$2:$AJ$2,0),0) -> 545.09976 | ... AN6: =VLOOKUP($B6,'DCS Data'!$E$2:$AJ$100,MATCH('Daily Report'!AN$1,'DCS Data'!$E$2:$AJ$2,0),0) -> 565.22322
A7: Feed to Mix point | B7: 60FR009.PV | C7: 60FQI009 | D7: 60FQI009 | E7: T/Day | F7: =F6+F57 -> 655.1 | G7: monthly_60FQI009 | H7: =SUM(I7:AN7) -> 15580.764 | I7: =VLOOKUP($B7,'DCS Data'!$E$2:$AJ$100,MATCH('Daily Report'!I$1,'DCS Data'!$E$2:$AJ$2,0),0) -> 475.72454 | K7: =VLOOKUP($B7,'DCS Data'!$E$2:$AJ$100,MATCH('Daily Report'!K$1,'DCS Data'!$E$2:$AJ$2,0),0) -> 516.54061 | L7: =VLOOKUP($B7,'DCS Data'!$E$2:$AJ$100,MATCH('Daily Report'!L$1,'DCS Data'!$E$2:$AJ$2,0),0) -> 512.95876 | M7: =VLOOKUP($B7,'DCS Data'!$E$2:$AJ$100,MATCH('Daily Report'!M$1,'DCS Data'!$E$2:$AJ$2,0),0) -> 511.42111 | N7: =VLOOKUP($B7,'DCS Data'!$E$2:$AJ$100,MATCH('Daily Report'!N$1,'DCS Data'!$E$2:$AJ$2,0),0) -> 515.50557 | O7: =VLOOKUP($B7,'DCS Data'!$E$2:$AJ$100,MATCH('Daily Report'!O$1,'DCS Data'!$E$2:$AJ$2,0),0) -> 521.90849 | P7: =VLOOKUP($B7,'DCS Data'!$E$2:$AJ$100,MATCH('Daily Report'!P$1,'DCS Data'!$E$2:$AJ$2,0),0) -> 518.61879 | Q7: =VLOOKUP($B7,'DCS Data'!$E$2:$AJ$100,MATCH('Daily Report'!Q$1,'DCS Data'!$E$2:$AJ$2,0),0) -> 510.02094 | R7: =VLOOKUP($B7,'DCS Data'!$E$2:$AJ$100,MATCH('Daily Report'!R$1,'DCS Data'!$E$2:$AJ$2,0),0) -> 503.76427 | ... AN7: =VLOOKUP($B7,'DCS Data'!$E$2:$AJ$100,MATCH('Daily Report'!AN$1,'DCS Data'!$E$2:$AJ$2,0),0) -> 513.36321
A8: Sales gas to fuel | B8: 60FR049.RAW | C8: 60FQI049 | D8: 60FQI049 | E8: T/Day | F8: 407.9 | G8: monthly_60FQI049 | H8: =SUM(I8:AN8) -> 10190.959 | I8: =VLOOKUP($B8,'DCS Data'!$E$2:$AJ$100,MATCH('Daily Report'!I$1,'DCS Data'!$E$2:$AJ$2,0),0) -> 296.67809 | K8: =VLOOKUP($B8,'DCS Data'!$E$2:$AJ$100,MATCH('Daily Report'!K$1,'DCS Data'!$E$2:$AJ$2,0),0) -> 321.30663 | L8: =VLOOKUP($B8,'DCS Data'!$E$2:$AJ$100,MATCH('Daily Report'!L$1,'DCS Data'!$E$2:$AJ$2,0),0) -> 320.61102 | M8: =VLOOKUP($B8,'DCS Data'!$E$2:$AJ$100,MATCH('Daily Report'!M$1,'DCS Data'!$E$2:$AJ$2,0),0) -> 319.78336 | N8: =VLOOKUP($B8,'DCS Data'!$E$2:$AJ$100,MATCH('Daily Report'!N$1,'DCS Data'!$E$2:$AJ$2,0),0) -> 323.75165 | O8: =VLOOKUP($B8,'DCS Data'!$E$2:$AJ$100,MATCH('Daily Report'!O$1,'DCS Data'!$E$2:$AJ$2,0),0) -> 331.00161 | P8: =VLOOKUP($B8,'DCS Data'!$E$2:$AJ$100,MATCH('Daily Report'!P$1,'DCS Data'!$E$2:$AJ$2,0),0) -> 330.32328 | Q8: =VLOOKUP($B8,'DCS Data'!$E$2:$AJ$100,MATCH('Daily Report'!Q$1,'DCS Data'!$E$2:$AJ$2,0),0) -> 328.08213 | R8: =VLOOKUP($B8,'DCS Data'!$E$2:$AJ$100,MATCH('Daily Report'!R$1,'DCS Data'!$E$2:$AJ$2,0),0) -> 327.44884 | ... AN8: =VLOOKUP($B8,'DCS Data'!$E$2:$AJ$100,MATCH('Daily Report'!AN$1,'DCS Data'!$E$2:$AJ$2,0),0) -> 336.56865
A9: Sales gas to fuel | B9: 60FR053.PV | C9: 60FQI053 | D9: 60FQI053 | E9: T/Day | F9: 407.9 | G9: monthly_60FQI053 | H9: =SUM(I9:AN9) -> 11136.04 | I9: =VLOOKUP($B9,'DCS Data'!$E$2:$AJ$100,MATCH('Daily Report'!I$1,'DCS Data'!$E$2:$AJ$2,0),0) -> 326.39421 | K9: =VLOOKUP($B9,'DCS Data'!$E$2:$AJ$100,MATCH('Daily Report'!K$1,'DCS Data'!$E$2:$AJ$2,0),0) -> 353.46819 | L9: =VLOOKUP($B9,'DCS Data'!$E$2:$AJ$100,MATCH('Daily Report'!L$1,'DCS Data'!$E$2:$AJ$2,0),0) -> 353.48294 | M9: =VLOOKUP($B9,'DCS Data'!$E$2:$AJ$100,MATCH('Daily Report'!M$1,'DCS Data'!$E$2:$AJ$2,0),0) -> 352.80551 | N9: =VLOOKUP($B9,'DCS Data'!$E$2:$AJ$100,MATCH('Daily Report'!N$1,'DCS Data'!$E$2:$AJ$2,0),0) -> 357.10757 | O9: =VLOOKUP($B9,'DCS Data'!$E$2:$AJ$100,MATCH('Daily Report'!O$1,'DCS Data'!$E$2:$AJ$2,0),0) -> 364.87162 | P9: =VLOOKUP($B9,'DCS Data'!$E$2:$AJ$100,MATCH('Daily Report'!P$1,'DCS Data'!$E$2:$AJ$2,0),0) -> 364.13954 | Q9: =VLOOKUP($B9,'DCS Data'!$E$2:$AJ$100,MATCH('Daily Report'!Q$1,'DCS Data'!$E$2:$AJ$2,0),0) -> 361.05856 | R9: =VLOOKUP($B9,'DCS Data'!$E$2:$AJ$100,MATCH('Daily Report'!R$1,'DCS Data'!$E$2:$AJ$2,0),0) -> 359.30059 | ... AN9: =VLOOKUP($B9,'DCS Data'!$E$2:$AJ$100,MATCH('Daily Report'!AN$1,'DCS Data'!$E$2:$AJ$2,0),0) -> 367.36664
A10: Sales Gas Average M.Wt | E10: T/Tmole | F10: 17.44 | G10: monthly_ | H10: =AVERAGE(I10:AN10) -> 17.316002 | I10: =Analysis!J12 -> 17.217801 | K10: =Analysis!L12 -> 17.24852 | L10: =Analysis!M12 -> 17.170369 | M10: =Analysis!N12 -> 17.176262 | N10: =Analysis!O12 -> 17.150428 | O10: =Analysis!P12 -> 17.176176 | P10: =Analysis!Q12 -> 17.193132 | Q10: =Analysis!R12 -> 17.217357 | R10: =Analysis!S12 -> 17.269731 | ... AN10: =Analysis!AO12 -> 17.223493
A11: HHV | B11: 927QR119.PV | C11: 927QR119 | D11: avg_hhv | E11: btu/scf | F11: 939.07 | G11: monthly_avg_hhv | H11: =AVERAGE(I11:AN11) -> 949.04456 | I11: =VLOOKUP($B11,'DCS Data'!$E$2:$AJ$100,MATCH('Daily Report'!I$1,'DCS Data'!$E$2:$AJ$2,0),0) -> 958.39106 | K11: =VLOOKUP($B11,'DCS Data'!$E$2:$AJ$100,MATCH('Daily Report'!K$1,'DCS Data'!$E$2:$AJ$2,0),0) -> 958.70493 | L11: =VLOOKUP($B11,'DCS Data'!$E$2:$AJ$100,MATCH('Daily Report'!L$1,'DCS Data'!$E$2:$AJ$2,0),0) -> 960.17631 | M11: =VLOOKUP($B11,'DCS Data'!$E$2:$AJ$100,MATCH('Daily Report'!M$1,'DCS Data'!$E$2:$AJ$2,0),0) -> 959.67176 | N11: =VLOOKUP($B11,'DCS Data'!$E$2:$AJ$100,MATCH('Daily Report'!N$1,'DCS Data'!$E$2:$AJ$2,0),0) -> 958.7671 | O11: =VLOOKUP($B11,'DCS Data'!$E$2:$AJ$100,MATCH('Daily Report'!O$1,'DCS Data'!$E$2:$AJ$2,0),0) -> 958.31932 | P11: =VLOOKUP($B11,'DCS Data'!$E$2:$AJ$100,MATCH('Daily Report'!P$1,'DCS Data'!$E$2:$AJ$2,0),0) -> 957.79165 | Q11: =VLOOKUP($B11,'DCS Data'!$E$2:$AJ$100,MATCH('Daily Report'!Q$1,'DCS Data'!$E$2:$AJ$2,0),0) -> 957.99171 | R11: =VLOOKUP($B11,'DCS Data'!$E$2:$AJ$100,MATCH('Daily Report'!R$1,'DCS Data'!$E$2:$AJ$2,0),0) -> 954.28132 | ... AN11: =VLOOKUP($B11,'DCS Data'!$E$2:$AJ$100,MATCH('Daily Report'!AN$1,'DCS Data'!$E$2:$AJ$2,0),0) -> 946.04552
D12: calc_HHV_927QR119 | E12: btu/nm3 | F12: =F11*38.0440529671749 -> 35726.029 | G12: monthly_calc_HHV_927QR119 | H12: =AVERAGE(I12:AN12) -> 36105.501 | I12: =I11*38.0440529671749 -> 36461.08 | K12: =K11*38.0440529671749 -> 36473.021 | L12: =L11*38.0440529671749 -> 36528.998 | M12: =M11*38.0440529671749 -> 36509.803 | N12: =N11*38.0440529671749 -> 36475.386 | O12: =O11*38.0440529671749 -> 36458.351 | P12: =P11*38.0440529671749 -> 36438.276 | Q12: =Q11*38.0440529671749 -> 36445.887 | R12: =R11*38.0440529671749 -> 36304.729 | ... AN12: =AN11*38.0440529671749 -> 35991.406
A13: Heating value from ARAMCO Metering HHV | D13: calc_Heating_Value_Metering_HHV | E13: btu/nm3 | G13: monthly_calc_Heating_Value_Metering_HHV | H13: =AVERAGE(I13:AN13) -> 35799.454 | I13: =I14*38.0440529671749 -> 35799.454 | K13: =K14*38.0440529671749 -> 35799.454 | L13: =L14*38.0440529671749 -> 35799.454 | M13: =M14*38.0440529671749 -> 35799.454 | N13: =N14*38.0440529671749 -> 35799.454 | O13: =O14*38.0440529671749 -> 35799.454 | P13: =P14*38.0440529671749 -> 35799.454 | Q13: =Q14*38.0440529671749 -> 35799.454 | R13: =R14*38.0440529671749 -> 35799.454 | ... AN13: =AN14*38.0440529671749 -> 35799.454
A14: Heating value from ARAMCO Metering HHV | E14: btu/SCF | G14: monthly_heating_value | H14: 941 | I14: =$H$14 -> 941 | K14: =$H$14 -> 941 | L14: =$H$14 -> 941 | M14: =$H$14 -> 941 | N14: =$H$14 -> 941 | O14: =$H$14 -> 941 | P14: =$H$14 -> 941 | Q14: =$H$14 -> 941 | R14: =$H$14 -> 941 | ... AN14: =$H$14 -> 941
A15: SELECTED HHV | D15: calc_Heating_Value_Metering_HHV | E15: btu/nm3 | G15: monthly_calc_Heating_Value_Metering_HHV | H15: =AVERAGE(I15:AN15) -> 35799.454 | I15: =I13 -> 35799.454 | K15: =K13 -> 35799.454 | L15: =L13 -> 35799.454 | M15: =M13 -> 35799.454 | N15: =N13 -> 35799.454 | O15: =O13 -> 35799.454 | P15: =P13 -> 35799.454 | Q15: =Q13 -> 35799.454 | R15: =R13 -> 35799.454 | ... AN15: =AN13 -> 35799.454
A16: Sales gas Feed Enegy rate | D16: calc_Sales_gas_Feed_Energy_Rate_MMBTU_Day | E16: MMBTU/Day | G16: monthly_calc_Sales_gas_Feed_Energy_Rate_MMBTU_Day | H16: =SUM(I16:AN16) -> 717033.45 | I16: =I15*((I7-I57)*1000/(I10/22.414))/1000000 -> 22007.304 | K16: =K15*((K7-K57)*1000/(K10/22.414))/1000000 -> 23866.899 | L16: =L15*((L7-L57)*1000/(L10/22.414))/1000000 -> 23808.132 | M16: =M15*((M7-M57)*1000/(M10/22.414))/1000000 -> 23728.115 | N16: =N15*((N7-N57)*1000/(N10/22.414))/1000000 -> 23954.961 | O16: =O15*((O7-O57)*1000/(O10/22.414))/1000000 -> 24218.174 | P16: =P15*((P7-P57)*1000/(P10/22.414))/1000000 -> 24040.766 | Q16: =Q15*((Q7-Q57)*1000/(Q10/22.414))/1000000 -> 23606.245 | R16: =R15*((R7-R57)*1000/(R10/22.414))/1000000 -> 23243.939 | ... AN16: =AN15*((AN7-AN57)*1000/(AN10/22.414))/1000000 -> 23753.54
A17: Sales gas Fuel Enegy rate | D17: calc_Sales_gas_Fuel_Energy_Rate_MMBTU_Day | E17: MMBTU/Day | G17: monthly_calc_Sales_gas_Fuel_Energy_Rate_MMBTU_Day | H17: =SUM(I17:AN17) -> 472230.67 | I17: =I15*(I8*1000/(I10/22.414))/1000000 -> 13826.223 | K17: =K15*(K8*1000/(K10/22.414))/1000000 -> 14947.33 | L17: =L15*(L8*1000/(L10/22.414))/1000000 -> 14982.855 | M17: =M15*(M8*1000/(M10/22.414))/1000000 -> 14939.05 | N17: =N15*(N8*1000/(N10/22.414))/1000000 -> 15147.215 | O17: =O15*(O8*1000/(O10/22.414))/1000000 -> 15463.201 | P17: =P15*(P8*1000/(P10/22.414))/1000000 -> 15416.293 | Q17: =Q15*(Q8*1000/(Q10/22.414))/1000000 -> 15290.154 | R17: =R15*(R8*1000/(R10/22.414))/1000000 -> 15214.358 | ... AN17: =AN15*(AN8*1000/(AN10/22.414))/1000000 -> 15680.078
A18: Total Sales gas Enegy rate (AF SalesGas) | D18: calc_Total_Sales_gas_Energy_rate | E18: MMBTU/Day | G18: monthly_calc_Total_Sales_gas_Energy_rate | H18: =SUM(I18:AN18) -> 1189264.1 | I18: =I17+I16 -> 35833.527 | K18: =K17+K16 -> 38814.229 | L18: =L17+L16 -> 38790.987 | M18: =M17+M16 -> 38667.165 | N18: =N17+N16 -> 39102.176 | O18: =O17+O16 -> 39681.375 | P18: =P17+P16 -> 39457.059 | Q18: =Q17+Q16 -> 38896.399 | R18: =R17+R16 -> 38458.297 | ... AN18: =AN17+AN16 -> 39433.617
A19: Fresh Gas from sulfinol absorber | B19: 60FR038.RAW | C19: 60FQI038 | D19: 60FQI038 | E19: T/Day | F19: 413.17 | G19: monthly_60FQI038 | H19: =SUM(I19:AN19) -> 10120.674 | I19: =VLOOKUP($B19,'DCS Data'!$E$2:$AJ$100,MATCH('Daily Report'!I$1,'DCS Data'!$E$2:$AJ$2,0),0) -> 304.7117 | K19: =VLOOKUP($B19,'DCS Data'!$E$2:$AJ$100,MATCH('Daily Report'!K$1,'DCS Data'!$E$2:$AJ$2,0),0) -> 334.80949 | L19: =VLOOKUP($B19,'DCS Data'!$E$2:$AJ$100,MATCH('Daily Report'!L$1,'DCS Data'!$E$2:$AJ$2,0),0) -> 333.98059 | M19: =VLOOKUP($B19,'DCS Data'!$E$2:$AJ$100,MATCH('Daily Report'!M$1,'DCS Data'!$E$2:$AJ$2,0),0) -> 332.17693 | N19: =VLOOKUP($B19,'DCS Data'!$E$2:$AJ$100,MATCH('Daily Report'!N$1,'DCS Data'!$E$2:$AJ$2,0),0) -> 335.66792 | O19: =VLOOKUP($B19,'DCS Data'!$E$2:$AJ$100,MATCH('Daily Report'!O$1,'DCS Data'!$E$2:$AJ$2,0),0) -> 337.06501 | P19: =VLOOKUP($B19,'DCS Data'!$E$2:$AJ$100,MATCH('Daily Report'!P$1,'DCS Data'!$E$2:$AJ$2,0),0) -> 335.78726 | Q19: =VLOOKUP($B19,'DCS Data'!$E$2:$AJ$100,MATCH('Daily Report'!Q$1,'DCS Data'!$E$2:$AJ$2,0),0) -> 330.61216 | R19: =VLOOKUP($B19,'DCS Data'!$E$2:$AJ$100,MATCH('Daily Report'!R$1,'DCS Data'!$E$2:$AJ$2,0),0) -> 326.62464 | ... AN19: =VLOOKUP($B19,'DCS Data'!$E$2:$AJ$100,MATCH('Daily Report'!AN$1,'DCS Data'!$E$2:$AJ$2,0),0) -> 336.5901
A20: Fresh gas to flare (Flare Payment) XOH | B20: 60FR045.RAW | C20: 60FQI045 | D20: 60FQI045 | E20: T/Day | F20: 0 | G20: monthly_60FQI045 | H20: =SUM(I20:AN20) -> 661.51291 | I20: =VLOOKUP($B20,'DCS Data'!$E$2:$AJ$100,MATCH('Daily Report'!I$1,'DCS Data'!$E$2:$AJ$2,0),0) -> 16.076682 | K20: =VLOOKUP($B20,'DCS Data'!$E$2:$AJ$100,MATCH('Daily Report'!K$1,'DCS Data'!$E$2:$AJ$2,0),0) -> 15.097068 | L20: =VLOOKUP($B20,'DCS Data'!$E$2:$AJ$100,MATCH('Daily Report'!L$1,'DCS Data'!$E$2:$AJ$2,0),0) -> 14.873856 | M20: =VLOOKUP($B20,'DCS Data'!$E$2:$AJ$100,MATCH('Daily Report'!M$1,'DCS Data'!$E$2:$AJ$2,0),0) -> 14.599687 | N20: =VLOOKUP($B20,'DCS Data'!$E$2:$AJ$100,MATCH('Daily Report'!N$1,'DCS Data'!$E$2:$AJ$2,0),0) -> 14.090603 | O20: =VLOOKUP($B20,'DCS Data'!$E$2:$AJ$100,MATCH('Daily Report'!O$1,'DCS Data'!$E$2:$AJ$2,0),0) -> 13.464697 | P20: =VLOOKUP($B20,'DCS Data'!$E$2:$AJ$100,MATCH('Daily Report'!P$1,'DCS Data'!$E$2:$AJ$2,0),0) -> 12.752191 | Q20: =VLOOKUP($B20,'DCS Data'!$E$2:$AJ$100,MATCH('Daily Report'!Q$1,'DCS Data'!$E$2:$AJ$2,0),0) -> 12.143387 | R20: =VLOOKUP($B20,'DCS Data'!$E$2:$AJ$100,MATCH('Daily Report'!R$1,'DCS Data'!$E$2:$AJ$2,0),0) -> 11.541502 | ... AN20: =VLOOKUP($B20,'DCS Data'!$E$2:$AJ$100,MATCH('Daily Report'!AN$1,'DCS Data'!$E$2:$AJ$2,0),0) -> 0.2430548
A21: Fresh gas to fuel header | B21: 60FR046.PV | C21: 60FQI046 | D21: 60FQI046 | E21: T/Day | F21: 0 | G21: monthly_60FQI046 | H21: =SUM(I21:AN21) -> 149.34979 | I21: =VLOOKUP($B21,'DCS Data'!$E$2:$AJ$100,MATCH('Daily Report'!I$1,'DCS Data'!$E$2:$AJ$2,0),0) -> 5.5759268 | K21: =VLOOKUP($B21,'DCS Data'!$E$2:$AJ$100,MATCH('Daily Report'!K$1,'DCS Data'!$E$2:$AJ$2,0),0) -> 4.7301031 | L21: =VLOOKUP($B21,'DCS Data'!$E$2:$AJ$100,MATCH('Daily Report'!L$1,'DCS Data'!$E$2:$AJ$2,0),0) -> 2.4825299 | M21: =VLOOKUP($B21,'DCS Data'!$E$2:$AJ$100,MATCH('Daily Report'!M$1,'DCS Data'!$E$2:$AJ$2,0),0) -> 3.0244137 | N21: =VLOOKUP($B21,'DCS Data'!$E$2:$AJ$100,MATCH('Daily Report'!N$1,'DCS Data'!$E$2:$AJ$2,0),0) -> 5.8323364 | O21: =VLOOKUP($B21,'DCS Data'!$E$2:$AJ$100,MATCH('Daily Report'!O$1,'DCS Data'!$E$2:$AJ$2,0),0) -> 4.2850126 | P21: =VLOOKUP($B21,'DCS Data'!$E$2:$AJ$100,MATCH('Daily Report'!P$1,'DCS Data'!$E$2:$AJ$2,0),0) -> 4.241413 | Q21: =VLOOKUP($B21,'DCS Data'!$E$2:$AJ$100,MATCH('Daily Report'!Q$1,'DCS Data'!$E$2:$AJ$2,0),0) -> 2.1824402 | R21: =VLOOKUP($B21,'DCS Data'!$E$2:$AJ$100,MATCH('Daily Report'!R$1,'DCS Data'!$E$2:$AJ$2,0),0) -> 2.9270617 | ... AN21: =VLOOKUP($B21,'DCS Data'!$E$2:$AJ$100,MATCH('Daily Report'!AN$1,'DCS Data'!$E$2:$AJ$2,0),0) -> 2.8229364
A22: Fresh gas to reformer fuel | B22: 60FR050.PV | C22: 60FQI050 | D22: 60FQI050 | E22: T/Day | F22: 0 | G22: monthly_60FQI050 | H22: =SUM(I22:AN22) -> 0 | I22: =VLOOKUP($B22,'DCS Data'!$E$2:$AJ$100,MATCH('Daily Report'!I$1,'DCS Data'!$E$2:$AJ$2,0),0) -> 0 | K22: =VLOOKUP($B22,'DCS Data'!$E$2:$AJ$100,MATCH('Daily Report'!K$1,'DCS Data'!$E$2:$AJ$2,0),0) -> 0 | L22: =VLOOKUP($B22,'DCS Data'!$E$2:$AJ$100,MATCH('Daily Report'!L$1,'DCS Data'!$E$2:$AJ$2,0),0) -> 0 | M22: =VLOOKUP($B22,'DCS Data'!$E$2:$AJ$100,MATCH('Daily Report'!M$1,'DCS Data'!$E$2:$AJ$2,0),0) -> 0 | N22: =VLOOKUP($B22,'DCS Data'!$E$2:$AJ$100,MATCH('Daily Report'!N$1,'DCS Data'!$E$2:$AJ$2,0),0) -> 0 | O22: =VLOOKUP($B22,'DCS Data'!$E$2:$AJ$100,MATCH('Daily Report'!O$1,'DCS Data'!$E$2:$AJ$2,0),0) -> 0 | P22: =VLOOKUP($B22,'DCS Data'!$E$2:$AJ$100,MATCH('Daily Report'!P$1,'DCS Data'!$E$2:$AJ$2,0),0) -> 0 | Q22: =VLOOKUP($B22,'DCS Data'!$E$2:$AJ$100,MATCH('Daily Report'!Q$1,'DCS Data'!$E$2:$AJ$2,0),0) -> 0 | R22: =VLOOKUP($B22,'DCS Data'!$E$2:$AJ$100,MATCH('Daily Report'!R$1,'DCS Data'!$E$2:$AJ$2,0),0) -> 0 | ... AN22: =VLOOKUP($B22,'DCS Data'!$E$2:$AJ$100,MATCH('Daily Report'!AN$1,'DCS Data'!$E$2:$AJ$2,0),0) -> 0
A23: PSA inlet flow | B23: 61FICA008.PV | C23: 61FQI008 | D23: 61FQI008 | E23: T/Day | F23: 432.1 | G23: monthly_61FQI008 | H23: =SUM(I23:AN23) -> 645.43459 | I23: =VLOOKUP($B23,'DCS Data'!$E$2:$AJ$100,MATCH('Daily Report'!I$1,'DCS Data'!$E$2:$AJ$2,0),0) -> 0.049699328 | K23: =VLOOKUP($B23,'DCS Data'!$E$2:$AJ$100,MATCH('Daily Report'!K$1,'DCS Data'!$E$2:$AJ$2,0),0) -> 0.048166376 | L23: =VLOOKUP($B23,'DCS Data'!$E$2:$AJ$100,MATCH('Daily Report'!L$1,'DCS Data'!$E$2:$AJ$2,0),0) -> 0.04724237 | M23: =VLOOKUP($B23,'DCS Data'!$E$2:$AJ$100,MATCH('Daily Report'!M$1,'DCS Data'!$E$2:$AJ$2,0),0) -> 0.045487498 | N23: =VLOOKUP($B23,'DCS Data'!$E$2:$AJ$100,MATCH('Daily Report'!N$1,'DCS Data'!$E$2:$AJ$2,0),0) -> 0.045305489 | O23: =VLOOKUP($B23,'DCS Data'!$E$2:$AJ$100,MATCH('Daily Report'!O$1,'DCS Data'!$E$2:$AJ$2,0),0) -> 0.044889122 | P23: =VLOOKUP($B23,'DCS Data'!$E$2:$AJ$100,MATCH('Daily Report'!P$1,'DCS Data'!$E$2:$AJ$2,0),0) -> 0.044950345 | Q23: =VLOOKUP($B23,'DCS Data'!$E$2:$AJ$100,MATCH('Daily Report'!Q$1,'DCS Data'!$E$2:$AJ$2,0),0) -> 0.045003778 | R23: =VLOOKUP($B23,'DCS Data'!$E$2:$AJ$100,MATCH('Daily Report'!R$1,'DCS Data'!$E$2:$AJ$2,0),0) -> 0.043762652 | ... AN23: =VLOOKUP($B23,'DCS Data'!$E$2:$AJ$100,MATCH('Daily Report'!AN$1,'DCS Data'!$E$2:$AJ$2,0),0) -> 38.108896
A24: SIPCHEM Import Hydrogen | B24: 170FIA220.PV | C24: 170FQQI220 | D24: 170FQQI220 | E24: T/Day | G24: monthly_170FQQI220 | H24: =SUM(I24:AN24) -> 1988.3695 | I24: =VLOOKUP($B24,'DCS Data'!$E$2:$AJ$100,MATCH('Daily Report'!I$1,'DCS Data'!$E$2:$AJ$2,0),0) -> 50.003629 | K24: =VLOOKUP($B24,'DCS Data'!$E$2:$AJ$100,MATCH('Daily Report'!K$1,'DCS Data'!$E$2:$AJ$2,0),0) -> 54.568473 | L24: =VLOOKUP($B24,'DCS Data'!$E$2:$AJ$100,MATCH('Daily Report'!L$1,'DCS Data'!$E$2:$AJ$2,0),0) -> 57.751508 | M24: =VLOOKUP($B24,'DCS Data'!$E$2:$AJ$100,MATCH('Daily Report'!M$1,'DCS Data'!$E$2:$AJ$2,0),0) -> 58.535966 | N24: =VLOOKUP($B24,'DCS Data'!$E$2:$AJ$100,MATCH('Daily Report'!N$1,'DCS Data'!$E$2:$AJ$2,0),0) -> 55.454159 | O24: =VLOOKUP($B24,'DCS Data'!$E$2:$AJ$100,MATCH('Daily Report'!O$1,'DCS Data'!$E$2:$AJ$2,0),0) -> 51.834799 | P24: =VLOOKUP($B24,'DCS Data'!$E$2:$AJ$100,MATCH('Daily Report'!P$1,'DCS Data'!$E$2:$AJ$2,0),0) -> 51.096089 | Q24: =VLOOKUP($B24,'DCS Data'!$E$2:$AJ$100,MATCH('Daily Report'!Q$1,'DCS Data'!$E$2:$AJ$2,0),0) -> 51.207506 | R24: =VLOOKUP($B24,'DCS Data'!$E$2:$AJ$100,MATCH('Daily Report'!R$1,'DCS Data'!$E$2:$AJ$2,0),0) -> 50.714458 | ... AN24: =VLOOKUP($B24,'DCS Data'!$E$2:$AJ$100,MATCH('Daily Report'!AN$1,'DCS Data'!$E$2:$AJ$2,0),0) -> 50.309055
B25: 170FI101.PV | C25: 170FQI101 | D25: 170FQI101 | E25: T/Day | G25: monthly_170FQI101 | H25: =SUM(I25:AN25) -> 1005.4726 | I25: =VLOOKUP($B25,'DCS Data'!$E$2:$AJ$100,MATCH('Daily Report'!I$1,'DCS Data'!$E$2:$AJ$2,0),0) -> 42.514937 | K25: =VLOOKUP($B25,'DCS Data'!$E$2:$AJ$100,MATCH('Daily Report'!K$1,'DCS Data'!$E$2:$AJ$2,0),0) -> 41.895091 | L25: =VLOOKUP($B25,'DCS Data'!$E$2:$AJ$100,MATCH('Daily Report'!L$1,'DCS Data'!$E$2:$AJ$2,0),0) -> 39.920453 | M25: =VLOOKUP($B25,'DCS Data'!$E$2:$AJ$100,MATCH('Daily Report'!M$1,'DCS Data'!$E$2:$AJ$2,0),0) -> 39.451488 | N25: =VLOOKUP($B25,'DCS Data'!$E$2:$AJ$100,MATCH('Daily Report'!N$1,'DCS Data'!$E$2:$AJ$2,0),0) -> 38.589994 | O25: =VLOOKUP($B25,'DCS Data'!$E$2:$AJ$100,MATCH('Daily Report'!O$1,'DCS Data'!$E$2:$AJ$2,0),0) -> 37.02885 | P25: =VLOOKUP($B25,'DCS Data'!$E$2:$AJ$100,MATCH('Daily Report'!P$1,'DCS Data'!$E$2:$AJ$2,0),0) -> 37.033204 | Q25: =VLOOKUP($B25,'DCS Data'!$E$2:$AJ$100,MATCH('Daily Report'!Q$1,'DCS Data'!$E$2:$AJ$2,0),0) -> 36.924792 | R25: =VLOOKUP($B25,'DCS Data'!$E$2:$AJ$100,MATCH('Daily Report'!R$1,'DCS Data'!$E$2:$AJ$2,0),0) -> 37.573208 | ... AN25: =VLOOKUP($B25,'DCS Data'!$E$2:$AJ$100,MATCH('Daily Report'!AN$1,'DCS Data'!$E$2:$AJ$2,0),0) -> 37.245255
A26: Segment#3 H2 | B26: 170FIC121.PV | C26: 170FQI121 | D26: 170FQI121 | E26: T/Day | G26: monthly_170FQI121 | H26: =SUM(I26:AN26) -> 843.97347 | I26: =VLOOKUP($B26,'DCS Data'!$E$2:$AJ$100,MATCH('Daily Report'!I$1,'DCS Data'!$E$2:$AJ$2,0),0) -> 0 | K26: =VLOOKUP($B26,'DCS Data'!$E$2:$AJ$100,MATCH('Daily Report'!K$1,'DCS Data'!$E$2:$AJ$2,0),0) -> 0 | L26: =VLOOKUP($B26,'DCS Data'!$E$2:$AJ$100,MATCH('Daily Report'!L$1,'DCS Data'!$E$2:$AJ$2,0),0) -> 0 | M26: =VLOOKUP($B26,'DCS Data'!$E$2:$AJ$100,MATCH('Daily Report'!M$1,'DCS Data'!$E$2:$AJ$2,0),0) -> 0 | N26: =VLOOKUP($B26,'DCS Data'!$E$2:$AJ$100,MATCH('Daily Report'!N$1,'DCS Data'!$E$2:$AJ$2,0),0) -> 0 | O26: =VLOOKUP($B26,'DCS Data'!$E$2:$AJ$100,MATCH('Daily Report'!O$1,'DCS Data'!$E$2:$AJ$2,0),0) -> 0 | P26: =VLOOKUP($B26,'DCS Data'!$E$2:$AJ$100,MATCH('Daily Report'!P$1,'DCS Data'!$E$2:$AJ$2,0),0) -> 0 | Q26: =VLOOKUP($B26,'DCS Data'!$E$2:$AJ$100,MATCH('Daily Report'!Q$1,'DCS Data'!$E$2:$AJ$2,0),0) -> 0 | R26: =VLOOKUP($B26,'DCS Data'!$E$2:$AJ$100,MATCH('Daily Report'!R$1,'DCS Data'!$E$2:$AJ$2,0),0) -> 0.92220037 | ... AN26: =VLOOKUP($B26,'DCS Data'!$E$2:$AJ$100,MATCH('Daily Report'!AN$1,'DCS Data'!$E$2:$AJ$2,0),0) -> 23.99913
B27: Net SIPCHEM Import | D27: calc_Net_SIPCHEM_Import_T_Day | E27: T/Day | G27: monthly_calc_Net_SIPCHEM_Import_T_Day | H27: =SUM(I27:AN27) -> 1090.2157 | I27: =MAX(I24-I25,I26) -> 7.4886921 | K27: =MAX(K24-K25,K26) -> 12.673382 | L27: =MAX(L24-L25,L26) -> 17.831055 | M27: =MAX(M24-M25,M26) -> 19.084479 | N27: =MAX(N24-N25,N26) -> 16.864165 | O27: =MAX(O24-O25,O26) -> 14.805949 | P27: =MAX(P24-P25,P26) -> 14.062886 | Q27: =MAX(Q24-Q25,Q26) -> 14.282715 | R27: =MAX(R24-R25,R26) -> 13.141249 | ... AN27: =MAX(AN24-AN25,AN26) -> 23.99913
A28: HMU H2 outlet | B28: 30FR026.PV | C28: 30FQI026 | D28: 30FQI026 | E28: T/Day | F28: 220 | G28: monthly_30FQI026 | H28: =SUM(I28:AN28) -> 9788.4332 | I28: =VLOOKUP($B28,'DCS Data'!$E$2:$AJ$100,MATCH('Daily Report'!I$1,'DCS Data'!$E$2:$AJ$2,0),0) -> 274.82855 | K28: =VLOOKUP($B28,'DCS Data'!$E$2:$AJ$100,MATCH('Daily Report'!K$1,'DCS Data'!$E$2:$AJ$2,0),0) -> 316.5105 | L28: =VLOOKUP($B28,'DCS Data'!$E$2:$AJ$100,MATCH('Daily Report'!L$1,'DCS Data'!$E$2:$AJ$2,0),0) -> 324.81535 | M28: =VLOOKUP($B28,'DCS Data'!$E$2:$AJ$100,MATCH('Daily Report'!M$1,'DCS Data'!$E$2:$AJ$2,0),0) -> 323.96956 | N28: =VLOOKUP($B28,'DCS Data'!$E$2:$AJ$100,MATCH('Daily Report'!N$1,'DCS Data'!$E$2:$AJ$2,0),0) -> 322.12721 | O28: =VLOOKUP($B28,'DCS Data'!$E$2:$AJ$100,MATCH('Daily Report'!O$1,'DCS Data'!$E$2:$AJ$2,0),0) -> 325.39024 | P28: =VLOOKUP($B28,'DCS Data'!$E$2:$AJ$100,MATCH('Daily Report'!P$1,'DCS Data'!$E$2:$AJ$2,0),0) -> 323.85949 | Q28: =VLOOKUP($B28,'DCS Data'!$E$2:$AJ$100,MATCH('Daily Report'!Q$1,'DCS Data'!$E$2:$AJ$2,0),0) -> 320.90933 | R28: =VLOOKUP($B28,'DCS Data'!$E$2:$AJ$100,MATCH('Daily Report'!R$1,'DCS Data'!$E$2:$AJ$2,0),0) -> 316.56838 | ... AN28: =VLOOKUP($B28,'DCS Data'!$E$2:$AJ$100,MATCH('Daily Report'!AN$1,'DCS Data'!$E$2:$AJ$2,0),0) -> 322.06536
A29: HMU H2 outlet Pressure | B29: 30PR026.PV | C29: 30PR026AI | D29: avg_hmu_h2_outlet_pressure | E29: bar g | G29: monthly_avg_hmu_h2_outlet_pressure | H29: =AVERAGE(I29:AN29) -> 14.704784 | I29: =VLOOKUP($B29,'DCS Data'!$E$2:$AJ$100,MATCH('Daily Report'!I$1,'DCS Data'!$E$2:$AJ$2,0),0) -> 14.791534 | K29: =VLOOKUP($B29,'DCS Data'!$E$2:$AJ$100,MATCH('Daily Report'!K$1,'DCS Data'!$E$2:$AJ$2,0),0) -> 14.781141 | L29: =VLOOKUP($B29,'DCS Data'!$E$2:$AJ$100,MATCH('Daily Report'!L$1,'DCS Data'!$E$2:$AJ$2,0),0) -> 14.698188 | M29: =VLOOKUP($B29,'DCS Data'!$E$2:$AJ$100,MATCH('Daily Report'!M$1,'DCS Data'!$E$2:$AJ$2,0),0) -> 14.754153 | N29: =VLOOKUP($B29,'DCS Data'!$E$2:$AJ$100,MATCH('Daily Report'!N$1,'DCS Data'!$E$2:$AJ$2,0),0) -> 14.786065 | O29: =VLOOKUP($B29,'DCS Data'!$E$2:$AJ$100,MATCH('Daily Report'!O$1,'DCS Data'!$E$2:$AJ$2,0),0) -> 14.805844 | P29: =VLOOKUP($B29,'DCS Data'!$E$2:$AJ$100,MATCH('Daily Report'!P$1,'DCS Data'!$E$2:$AJ$2,0),0) -> 14.789062 | Q29: =VLOOKUP($B29,'DCS Data'!$E$2:$AJ$100,MATCH('Daily Report'!Q$1,'DCS Data'!$E$2:$AJ$2,0),0) -> 14.748245 | R29: =VLOOKUP($B29,'DCS Data'!$E$2:$AJ$100,MATCH('Daily Report'!R$1,'DCS Data'!$E$2:$AJ$2,0),0) -> 14.792283 | ... AN29: =VLOOKUP($B29,'DCS Data'!$E$2:$AJ$100,MATCH('Daily Report'!AN$1,'DCS Data'!$E$2:$AJ$2,0),0) -> 14.559003
A30: HMU H2 outlet Temperature | B30: 30TI-316.PV | C30: 30TI-316 | D30: avg_hmu_h2_outlet_temprature | E30: 0C | G30: monthly_avg_hmu_h2_outlet_temprature | H30: =AVERAGE(I30:AN30) -> 37.962987 | I30: =VLOOKUP($B30,'DCS Data'!$E$2:$AJ$100,MATCH('Daily Report'!I$1,'DCS Data'!$E$2:$AJ$2,0),0) -> 45.833715 | K30: =VLOOKUP($B30,'DCS Data'!$E$2:$AJ$100,MATCH('Daily Report'!K$1,'DCS Data'!$E$2:$AJ$2,0),0) -> 45.017124 | L30: =VLOOKUP($B30,'DCS Data'!$E$2:$AJ$100,MATCH('Daily Report'!L$1,'DCS Data'!$E$2:$AJ$2,0),0) -> 44.405759 | M30: =VLOOKUP($B30,'DCS Data'!$E$2:$AJ$100,MATCH('Daily Report'!M$1,'DCS Data'!$E$2:$AJ$2,0),0) -> 43.565906 | N30: =VLOOKUP($B30,'DCS Data'!$E$2:$AJ$100,MATCH('Daily Report'!N$1,'DCS Data'!$E$2:$AJ$2,0),0) -> 43.995716 | O30: =VLOOKUP($B30,'DCS Data'!$E$2:$AJ$100,MATCH('Daily Report'!O$1,'DCS Data'!$E$2:$AJ$2,0),0) -> 44.407769 | P30: =VLOOKUP($B30,'DCS Data'!$E$2:$AJ$100,MATCH('Daily Report'!P$1,'DCS Data'!$E$2:$AJ$2,0),0) -> 44.868529 | Q30: =VLOOKUP($B30,'DCS Data'!$E$2:$AJ$100,MATCH('Daily Report'!Q$1,'DCS Data'!$E$2:$AJ$2,0),0) -> 44.79797 | R30: =VLOOKUP($B30,'DCS Data'!$E$2:$AJ$100,MATCH('Daily Report'!R$1,'DCS Data'!$E$2:$AJ$2,0),0) -> 44.403776 | ... AN30: =VLOOKUP($B30,'DCS Data'!$E$2:$AJ$100,MATCH('Daily Report'!AN$1,'DCS Data'!$E$2:$AJ$2,0),0) -> 32.992042
B31: 30-FR-026.COR | D31: calc_HMU_H2_outlet_T_Day | E31: T/Day | G31: monthly_calc_HMU_H2_outlet_T_Day | H31: =SUM(I31:AN31) -> 9793.5958 | I31: =(I28*(((57+273)/(I30+273))*(2.6/Analysis!J60)*((I29+1.01325)/(14.6+1.01325)))^0.5)*(Analysis!J60/2.6)-I27 -> 295.12866 | K31: =(K28*(((57+273)/(K30+273))*(2.6/Analysis!L60)*((K29+1.01325)/(14.6+1.01325)))^0.5)*(Analysis!L60/2.6)-K27 -> 336.17292 | L31: =(L28*(((57+273)/(L30+273))*(2.6/Analysis!M60)*((L29+1.01325)/(14.6+1.01325)))^0.5)*(Analysis!M60/2.6)-L27 -> 339.57089 | M31: =(M28*(((57+273)/(M30+273))*(2.6/Analysis!N60)*((M29+1.01325)/(14.6+1.01325)))^0.5)*(Analysis!N60/2.6)-M27 -> 338.49455 | N31: =(N28*(((57+273)/(N30+273))*(2.6/Analysis!O60)*((N29+1.01325)/(14.6+1.01325)))^0.5)*(Analysis!O60/2.6)-N27 -> 338.79963 | O31: =(O28*(((57+273)/(O30+273))*(2.6/Analysis!P60)*((O29+1.01325)/(14.6+1.01325)))^0.5)*(Analysis!P60/2.6)-O27 -> 344.45198 | P31: =(P28*(((57+273)/(P30+273))*(2.6/Analysis!Q60)*((P29+1.01325)/(14.6+1.01325)))^0.5)*(Analysis!Q60/2.6)-P27 -> 343.05613 | Q31: =(Q28*(((57+273)/(Q30+273))*(2.6/Analysis!R60)*((Q29+1.01325)/(14.6+1.01325)))^0.5)*(Analysis!R60/2.6)-Q27 -> 339.1651 | R31: =(R28*(((57+273)/(R30+273))*(2.6/Analysis!S60)*((R29+1.01325)/(14.6+1.01325)))^0.5)*(Analysis!S60/2.6)-R27 -> 336.22896 | ... AN31: =(AN28*(((57+273)/(AN30+273))*(2.6/Analysis!AO60)*((AN29+1.01325)/(14.6+1.01325)))^0.5)*(Analysis!AO60/2.6)-AN27 -> 335.32342
